Workbook

Sheet Product Backlog
A1: ID | B1: Epic | C1: User story | D1: Tiêu chí chấp nhận | E1: Ưu tiên | F1: Story point | G1: Sprint | H1: Bản phát hành | I1: Yêu cầu liên quan | J1: Trạng thái | K1: Ghi chú
A2: A1 | B2: A. Thư viện kiến thức | C2: Là học sinh, tôi muốn xem danh sách các loại tứ giác để biết mình cần học những hình nào | D2: Hiển thị danh sách hình theo lớp đã chọn, có tên và hình nhỏ; bấm vào mở chi tiết | E2: M | F2: 3 | G2: 1 | H2: MVP | I2: FR-01 | J2: Hoàn thành | K2: Danh sách hình lọc theo lớp (api /api/hinh)
A3: A2 | B3: A. Thư viện kiến thức | C3: Là học sinh, tôi muốn xem thẻ kiến thức của từng hình (định nghĩa, tính chất, dấu hiệu, công thức) | D3: Đủ các mục theo Phụ lục A của hồ sơ đặc tả; công thức hiển thị đúng ký hiệu | E3: M | F3: 8 | G3: 1 | H3: MVP | I3: FR-02 | J3: Hoàn thành | K3: Có định nghĩa, tính chất, dấu hiệu, công thức; chưa có mục Ví dụ
A4: A3 | B4: A. Thư viện kiến thức | C4: Là học sinh, tôi muốn xem hình minh họa có ký hiệu cạnh bằng, song song, góc vuông | D4: Hình vẽ đúng ký hiệu chuẩn sách giáo khoa | E4: M | F4: 5 | G4: 1 | H4: MVP | I4: FR-03 | J4: Chưa làm
A5: A4 | B5: A. Thư viện kiến thức | C5: Là học sinh, tôi muốn xem sơ đồ quan hệ giữa các hình để hiểu hình nào nằm trong hình nào | D5: Sơ đồ bao hàm đúng; bấm vào nút nhảy tới thẻ hình | E5: M | F5: 5 | G5: 2 | H5: MVP | I5: FR-04 | J5: Hoàn thành | K5: Sơ đồ xếp tầng dạng danh sách, từ lớp 8; chưa vẽ đồ thị
A6: A5 | B6: A. Thư viện kiến thức | C6: Là học sinh, tôi muốn xem bảng so sánh các hình để phân biệt nhanh | D6: Bảng so sánh đúng; cuộn ngang được trên điện thoại | E6: S | F6: 3 | G6: 2 | H6: MVP | I6: FR-05 | J6: Chưa làm
A7: A6 | B7: A. Thư viện kiến thức | C7: Là học sinh, tôi muốn thấy mẹo nhớ ngắn cho mỗi hình | D7: Mỗi hình có ít nhất 1 mẹo, tối đa 2 câu | E7: C | F7: 2 | G7: 5 | H7: 1.1 | I7: FR-02 | J7: Chưa làm
A8: B1 | B8: B. Tra cứu và nhận diện | C8: Là học sinh, tôi muốn tìm hình theo tên | D8: Tìm không phân biệt hoa thường, có hoặc không dấu | E8: S | F8: 3 | G8: 2 | H8: MVP | I8: FR-05 | J8: Chưa làm
A9: B2 | B9: B. Tra cứu và nhận diện | C9: Là học sinh, tôi muốn lọc hình theo đặc điểm | D9: Lọc nhiều điều kiện cùng lúc, kết quả đúng bảng so sánh | E9: S | F9: 5 | G9: 5 | H9: 1.1 | I9: FR-05 | J9: Chưa làm
A10: B3 | B10: B. Tra cứu và nhận diện | C10: Là học sinh, tôi muốn chọn các đặc điểm đã biết và nhận gợi ý đó là hình gì | D10: Trả về hình phù hợp nhất kèm giải thích; báo "không đủ dữ kiện" nếu thiếu | E10: S | F10: 8 | G10: 5 | H10: 1.1 | I10: FR-07 | J10: Chưa làm
A11: B4 | B11: B. Tra cứu và nhận diện | C11: Là học sinh, tôi muốn kéo đỉnh của hình để thấy tính chất luôn đúng | D11: Kéo mượt; ký hiệu tự cập nhật; hình không thoát khỏi loại đang học | E11: S | F11: 13 | G11: 6 | H11: 1.1 | I11: FR-03 | J11: Chưa làm
A12: C1 | B12: C. Luyện tập và ôn tập | C12: Là học sinh, tôi muốn làm câu nhận diện tên hình | D12: Ngân hàng ít nhất 40 câu, 2 mức độ, phản hồi đúng sai tức thì | E12: M | F12: 8 | G12: 2 | H12: MVP | I12: FR-06, FR-08 | J12: Đang làm | K12: Có dạng định nghĩa → tên hình; chưa đủ 40 câu, chưa có 2 mức độ
A13: C2 | B13: C. Luyện tập và ôn tập | C13: Là học sinh, tôi muốn làm câu hỏi về tính chất | D13: Ít nhất 30 câu, có giải thích | E13: M | F13: 5 | G13: 2 | H13: MVP | I13: FR-08 | J13: Chưa làm
A14: C3 | B14: C. Luyện tập và ôn tập | C14: Là học sinh, tôi muốn làm câu hỏi về dấu hiệu nhận biết | D14: Ít nhất 30 câu, có giải thích | E14: M | F14: 5 | G14: 3 | H14: MVP | I14: FR-08 | J14: Đang làm | K14: Có dạng dấu hiệu → kết luận (khoảng 24 câu); chưa đủ 30 câu, chưa có giải thích
A15: C4 | B15: C. Luyện tập và ôn tập | C15: Là học sinh, tôi muốn làm câu hỏi phân biệt "tính chất" và "dấu hiệu" | D15: Ít nhất 20 câu tình huống | E15: S | F15: 5 | G15: 5 | H15: 1.1 | I15: FR-08 | J15: Chưa làm
A16: C5 | B16: C. Luyện tập và ôn tập | C16: Là học sinh, tôi muốn làm bài tập công thức chu vi, diện tích, đường chéo | D16: Ít nhất 30 câu, số liệu ngẫu nhiên, đáp án kèm bước giải | E16: M | F16: 8 | G16: 3 | H16: MVP | I16: FR-08 | J16: Đang làm | K16: Có dạng công thức → tên hình; chưa có bài tính số liệu và bước giải
A17: C6 | B17: C. Luyện tập và ôn tập | C17: Là học sinh, tôi muốn dùng máy tính công thức để kiểm tra kết quả | D17: Nhập số, hiển thị bước thế số, báo lỗi dữ liệu không hợp lệ | E17: S | F17: 5 | G17: 5 | H17: 1.1 | I17: FR-09 | J17: Chưa làm
A18: C7 | B18: C. Luyện tập và ôn tập | C18: Là học sinh, tôi muốn ôn flashcard theo lịch lặp lại | D18: Thẻ sai lặp lại sớm hơn; có nút đã nhớ / chưa nhớ | E18: S | F18: 8 | G18: 6 | H18: 1.1 | I18: FR-10 | J18: Chưa làm
A19: C8 | B19: C. Luyện tập và ôn tập | C19: Là học sinh, tôi muốn làm bài kiểm tra tổng hợp | D19: 10–20 câu trộn dạng, có điểm và lời giải | E19: M | F19: 8 | G19: 4 | H19: MVP | I19: FR-12 | J19: Chưa làm
A20: D1 | B20: D. Theo dõi tiến độ | C20: Là học sinh, tôi muốn xem điểm theo từng chủ đề | D20: Biểu đồ hoặc phần trăm theo hình và theo dạng bài | E20: S | F20: 5 | G20: 5 | H20: 1.1 | I20: FR-11 | J20: Chưa làm
A21: D2 | B21: D. Theo dõi tiến độ | C21: Là học sinh, tôi muốn xem danh sách thẻ hay sai | D21: Sắp theo số lần sai, bấm để ôn lại | E21: S | F21: 3 | G21: 5 | H21: 1.1 | I21: FR-11 | J21: Chưa làm
A22: D3 | B22: D. Theo dõi tiến độ | C22: Là học sinh, tôi muốn có chuỗi ngày học và huy hiệu để có động lực | D22: Chuỗi tính theo ngày; huy hiệu cơ bản | E22: C | F22: 5 | G22: 6 | H22: 1.1 | I22: FR-11 | J22: Chưa làm
A23: E1 | B23: E. Tài khoản và giáo viên | C23: Là học sinh, tôi muốn đăng nhập để lưu tiến độ trên nhiều thiết bị | D23: Đăng ký, đăng nhập, quên mật khẩu, đồng bộ | E23: S | F23: 13 | G23: 5 | H23: 1.1 | I23: FR-13 | J23: Chưa làm
A24: E2 | B24: E. Tài khoản và giáo viên | C24: Là giáo viên, tôi muốn tạo lớp và mời học sinh bằng mã | D24: Mã lớp, danh sách học sinh | E24: C | F24: 8 | G24: 9 | H24: 2.0 | I24: FR-14 | J24: Chưa làm
A25: E3 | B25: E. Tài khoản và giáo viên | C25: Là giáo viên, tôi muốn giao bài và xem báo cáo cả lớp | D25: Giao theo chủ đề và khối lớp; báo cáo điểm và lỗi sai phổ biến | E25: C | F25: 13 | G25: 10 | H25: 2.0 | I25: FR-14 | J25: Chưa làm
A26: E4 | B26: E. Tài khoản và giáo viên | C26: Là giáo viên, tôi muốn thêm hoặc sửa câu hỏi của riêng mình | D26: Giao diện quản lý ngân hàng câu hỏi, duyệt trước khi dùng | E26: C | F26: 13 | G26: 10 | H26: 2.0 | I26: FR-14 | J26: Chưa làm
A27: F1 | B27: F. Nền tảng kỹ thuật và chất lượng | C27: Thiết lập dự án, CI/CD, môi trường thử nghiệm | D27: Triển khai tự động lên môi trường thử nghiệm | E27: M | F27: 5 | G27: 1 | H27: MVP | I27: NFR | J27: Chưa làm
A28: F2 | B28: F. Nền tảng kỹ thuật và chất lượng | C28: Thiết kế UI/UX và design system | D28: Bộ màn hình chính, được Product Owner duyệt | E28: M | F28: 8 | G28: 1 | H28: MVP | I28: NFR | J28: Chưa làm
A29: F3 | B29: F. Nền tảng kỹ thuật và chất lượng | C29: Hiển thị công thức toán chuẩn | D29: Dùng LaTeX hoặc MathML, hiển thị đúng trên điện thoại | E29: M | F29: 3 | G29: 1 | H29: MVP | I29: NFR | J29: Chưa làm
A30: F4 | B30: F. Nền tảng kỹ thuật và chất lượng | C30: Kiểm duyệt nội dung bởi giáo viên | D30: Mọi thẻ và câu hỏi có trạng thái "đã duyệt" | E30: M | F30: 5 | G30: Liên tục | H30: MVP | I30: BR-08 | J30: Chưa làm
A31: F5 | B31: F. Nền tảng kỹ thuật và chất lượng | C31: Kiểm thử khả dụng với 5–10 học sinh | D31: Báo cáo lỗi và danh sách cải tiến | E31: S | F31: 5 | G31: 4 | H31: MVP | I31: NFR | J31: Chưa làm
A32: F6 | B32: F. Nền tảng kỹ thuật và chất lượng | C32: Bảo mật, quyền riêng tư dữ liệu học sinh | D32: Rà soát trước khi có tài khoản | E32: M | F32: 5 | G32: 5 | H32: 1.1 | I32: NFR | J32: Chưa làm
A33: G1 | B33: G. Cá nhân hóa theo khối lớp (6–12) | C33: Là học sinh, tôi muốn chọn lớp (6–12) khi bắt đầu để chỉ thấy nội dung phù hợp | D33: Màn hình chọn lớp lần đầu; đổi lớp trong Cài đặt; không mất tiến độ | E33: M | F33: 3 | G33: 1 | H33: MVP | I33: FR-15 | J33: Hoàn thành | K33: Chọn lớp 6–12, nhớ bằng localStorage
A34: G2 | B34: G. Cá nhân hóa theo khối lớp (6–12) | C34: Là đội phát triển, chúng tôi cần mô hình nội dung gắn nhãn lớp, mức độ, bộ sách, trạng thái duyệt | D34: Mọi thẻ, câu hỏi, công thức có đủ thuộc tính theo BR-07 | E34: M | F34: 5 | G34: 1 | H34: MVP | I34: FR-16, BR-07 | J34: Đang làm | K34: Đã có lop_min; chưa có mức độ, bộ sách, trạng thái duyệt (BR-07)
A35: G3 | B35: G. Cá nhân hóa theo khối lớp (6–12) | C35: Là học sinh, tôi muốn thẻ kiến thức, câu hỏi, công thức được lọc theo lớp | D35: Không hiển thị nội dung ngoài lớp (trừ khi xem trước) | E35: M | F35: 5 | G35: 2 | H35: MVP | I35: FR-16 | J35: Hoàn thành | K35: Lọc hình, tính chất, dấu hiệu, công thức, câu hỏi theo lớp
A36: G4 | B36: G. Cá nhân hóa theo khối lớp (6–12) | C36: Là học sinh, tôi muốn xem trước lớp trên và ôn lại lớp dưới | D36: Nhãn "Sẽ học ở lớp X" và "Ôn lớp Y"; bật tắt được | E36: S | F36: 5 | G36: 5 | H36: 1.1 | I36: FR-17, FR-18 | J36: Đang làm | K36: Có nhãn Ôn tập; chưa có chế độ xem trước lớp trên
A37: G5 | B37: G. Cá nhân hóa theo khối lớp (6–12) | C37: Là học sinh lớp 6, tôi muốn học 5 hình, đối xứng, chu vi, diện tích | D37: Ít nhất 40 câu hỏi; hình động; đúng phạm vi lớp 6 | E37: M | F37: 8 | G37: 2 | H37: MVP | I37: FR-16 | J37: Đang làm | K37: Có 5 hình lớp 6, chu vi, diện tích; chưa có đối xứng, chưa đủ 40 câu
A38: G6 | B38: G. Cá nhân hóa theo khối lớp (6–12) | C38: Là học sinh lớp 7, tôi muốn ôn lớp 6 và học hình khối có đáy là tứ giác | D38: Ít nhất 30 câu hỏi; công thức lăng trụ, hình hộp | E38: S | F38: 5 | G38: 5 | H38: 1.1 | I38: FR-16 | J38: Chưa làm
A39: G7 | B39: G. Cá nhân hóa theo khối lớp (6–12) | C39: Gắn nhãn lớp 8 cho toàn bộ nội dung Epic A–C đã có | D39: Mọi mục lớp 8 có nhãn lớp và mức độ | E39: M | F39: 3 | G39: 1 | H39: MVP | I39: FR-16 | J39: Hoàn thành | K39: Nội dung lớp 8 trong data.py đều có lop_min
A40: G8 | B40: G. Cá nhân hóa theo khối lớp (6–12) | C40: Là học sinh lớp 9, tôi muốn học tứ giác nội tiếp và ôn thi vào lớp 10 | D40: Thẻ kiến thức, ít nhất 30 câu, bộ đề ôn | E40: S | F40: 8 | G40: 6 | H40: 1.1 | I40: FR-16, FR-21 | J40: Đang làm | K40: Có tứ giác nội tiếp; chưa có bộ đề ôn thi vào 10
...

Sheet Tổng hợp
A1: Tổng hợp Product Backlog – Công cụ học tứ giác lớp 6–12
A3: Theo Epic | E3: Theo trạng thái
A4: Epic | B4: Số story | C4: Tổng story point | E4: Trạng thái | F4: Số story | G4: Tổng story point
A5: A. Thư viện kiến thức | B5: =COUNTIF('Product Backlog'!$B$2:$B$200,A5) -> 6 | C5: =SUMIF('Product Backlog'!$B$2:$B$200,A5,'Product Backlog'!$F$2:$F$200) -> 26 | E5: Chưa làm | F5: =COUNTIF('Product Backlog'!$J$2:$J$200,E5) -> 34 | G5: =SUMIF('Product Backlog'!$J$2:$J$200,E5,'Product Backlog'!$F$2:$F$200) -> 218
A6: B. Tra cứu và nhận diện | B6: =COUNTIF('Product Backlog'!$B$2:$B$200,A6) -> 4 | C6: =SUMIF('Product Backlog'!$B$2:$B$200,A6,'Product Backlog'!$F$2:$F$200) -> 29 | E6: Đang làm | F6: =COUNTIF('Product Backlog'!$J$2:$J$200,E6) -> 8 | G6: =SUMIF('Product Backlog'!$J$2:$J$200,E6,'Product Backlog'!$F$2:$F$200) -> 50
A7: C. Luyện tập và ôn tập | B7: =COUNTIF('Product Backlog'!$B$2:$B$200,A7) -> 8 | C7: =SUMIF('Product Backlog'!$B$2:$B$200,A7,'Product Backlog'!$F$2:$F$200) -> 52 | E7: Hoàn thành | F7: =COUNTIF('Product Backlog'!$J$2:$J$200,E7) -> 11 | G7: =SUMIF('Product Backlog'!$J$2:$J$200,E7,'Product Backlog'!$F$2:$F$200) -> 51
A8: D. Theo dõi tiến độ | B8: =COUNTIF('Product Backlog'!$B$2:$B$200,A8) -> 3 | C8: =SUMIF('Product Backlog'!$B$2:$B$200,A8,'Product Backlog'!$F$2:$F$200) -> 13
A9: E. Tài khoản và giáo viên | B9: =COUNTIF('Product Backlog'!$B$2:$B$200,A9) -> 4 | C9: =SUMIF('Product Backlog'!$B$2:$B$200,A9,'Product Backlog'!$F$2:$F$200) -> 47
A10: F. Nền tảng kỹ thuật và chất lượng | B10: =COUNTIF('Product Backlog'!$B$2:$B$200,A10) -> 6 | C10: =SUMIF('Product Backlog'!$B$2:$B$200,A10,'Product Backlog'!$F$2:$F$200) -> 31
A11: G. Cá nhân hóa theo khối lớp (6–12) | B11: =COUNTIF('Product Backlog'!$B$2:$B$200,A11) -> 14 | C11: =SUMIF('Product Backlog'!$B$2:$B$200,A11,'Product Backlog'!$F$2:$F$200) -> 81
A12: H. Cơ sở dữ liệu đồ thị Neo4j | B12: =COUNTIF('Product Backlog'!$B$2:$B$200,A12) -> 8 | C12: =SUMIF('Product Backlog'!$B$2:$B$200,A12,'Product Backlog'!$F$2:$F$200) -> 40
A13: Tổng | B13: =SUM(B5:B12) -> 53 | C13: =SUM(C5:C12) -> 319
A14: Kiểm tra khớp với bảng backlog | B14: =IF(B13=COUNTA('Product Backlog'!$A$2:$A$200),"Khớp","Lệch") -> Khớp | C14: =IF(C13=SUM('Product Backlog'!$F$2:$F$200),"Khớp","Lệch") -> Khớp
A16: Theo mức ưu tiên (MoSCoW)
A17: Ưu tiên | B17: Số story | C17: Tổng story point
A18: M – Must (bắt buộc) | B18: =COUNTIF('Product Backlog'!$E$2:$E$200,"M") -> 25 | C18: =SUMIF('Product Backlog'!$E$2:$E$200,"M",'Product Backlog'!$F$2:$F$200) -> 132
A19: S – Should (nên có) | B19: =COUNTIF('Product Backlog'!$E$2:$E$200,"S") -> 18 | C19: =SUMIF('Product Backlog'!$E$2:$E$200,"S",'Product Backlog'!$F$2:$F$200) -> 109
A20: C – Could (có thể có) | B20: =COUNTIF('Product Backlog'!$E$2:$E$200,"C") -> 10 | C20: =SUMIF('Product Backlog'!$E$2:$E$200,"C",'Product Backlog'!$F$2:$F$200) -> 78
A22: Theo bản phát hành
A23: Bản phát hành | B23: Số story | C23: Tổng story point
A24: MVP (Sprint 1–4) | B24: =COUNTIF('Product Backlog'!$H$2:$H$200,"MVP") -> 27 | C24: =SUMIF('Product Backlog'!$H$2:$H$200,"MVP",'Product Backlog'!$F$2:$F$200) -> 138
A25: Bản 1.1 (Sprint 5–6) | B25: =COUNTIF('Product Backlog'!$H$2:$H$200,"1.1") -> 19 | C25: =SUMIF('Product Backlog'!$H$2:$H$200,"1.1",'Product Backlog'!$F$2:$F$200) -> 115
A26: Bản 1.2 (Sprint 7–8) | B26: =COUNTIF('Product Backlog'!$H$2:$H$200,"1.2") -> 4 | C26: =SUMIF('Product Backlog'!$H$2:$H$200,"1.2",'Product Backlog'!$F$2:$F$200) -> 32
A27: Bản 2.0 (Sprint 9+) | B27: =COUNTIF('Product Backlog'!$H$2:$H$200,"2.0") -> 3 | C27: =SUMIF('Product Backlog'!$H$2:$H$200,"2.0",'Product Backlog'!$F$2:$F$200) -> 34
A29: Story point theo sprint
A30: Sprint | B30: Số story | C30: Tổng story point
A31: 1 | B31: =COUNTIF('Product Backlog'!$G$2:$G$200,A31) -> 11 | C31: =SUMIF('Product Backlog'!$G$2:$G$200,A31,'Product Backlog'!$F$2:$F$200) -> 51
A32: 2 | B32: =COUNTIF('Product Backlog'!$G$2:$G$200,A32) -> 10 | C32: =SUMIF('Product Backlog'!$G$2:$G$200,A32,'Product Backlog'!$F$2:$F$200) -> 51
A33: 3 | B33: =COUNTIF('Product Backlog'!$G$2:$G$200,A33) -> 2 | C33: =SUMIF('Product Backlog'!$G$2:$G$200,A33,'Product Backlog'!$F$2:$F$200) -> 13
A34: 4 | B34: =COUNTIF('Product Backlog'!$G$2:$G$200,A34) -> 2 | C34: =SUMIF('Product Backlog'!$G$2:$G$200,A34,'Product Backlog'!$F$2:$F$200) -> 13
A35: 5 | B35: =COUNTIF('Product Backlog'!$G$2:$G$200,A35) -> 14 | C35: =SUMIF('Product Backlog'!$G$2:$G$200,A35,'Product Backlog'!$F$2:$F$200) -> 76
A36: 6 | B36: =COUNTIF('Product Backlog'!$G$2:$G$200,A36) -> 5 | C36: =SUMIF('Product Backlog'!$G$2:$G$200,A36,'Product Backlog'!$F$2:$F$200) -> 39
A37: 7 | B37: =COUNTIF('Product Backlog'!$G$2:$G$200,A37) -> 1 | C37: =SUMIF('Product Backlog'!$G$2:$G$200,A37,'Product Backlog'!$F$2:$F$200) -> 8
A38: 8 | B38: =COUNTIF('Product Backlog'!$G$2:$G$200,A38) -> 3 | C38: =SUMIF('Product Backlog'!$G$2:$G$200,A38,'Product Backlog'!$F$2:$F$200) -> 24
A39: 9 | B39: =COUNTIF('Product Backlog'!$G$2:$G$200,A39) -> 1 | C39: =SUMIF('Product Backlog'!$G$2:$G$200,A39,'Product Backlog'!$F$2:$F$200) -> 8
A40: 10 | B40: =COUNTIF('Product Backlog'!$G$2:$G$200,A40) -> 2 | C40: =SUMIF('Product Backlog'!$G$2:$G$200,A40,'Product Backlog'!$F$2:$F$200) -> 26
A41: Liên tục (không theo sprint) | B41: =COUNTIF('Product Backlog'!$G$2:$G$200,"Liên tục") -> 2 | C41: =SUMIF('Product Backlog'!$G$2:$G$200,"Liên tục",'Product Backlog'!$F$2:$F$200) -> 10
A43: Ghi chú:
A44: - Story point và sprint là ước lượng ban đầu, cần đội phát triển xác nhận khi lập kế hoạch sprint.
A45: - Ưu tiên theo MoSCoW: M = Must, S = Should, C = Could.
...
